Workbook

Sheet VPR
A1: GROUP A — REQUIREMENT IDENTITY (pssgen import — do not edit) | G1: GROUP B — VERIFICATION PLANNING (engineer) | P1: GROUP C — IMPLEMENTATION (engineer) | S1: GROUP D — EXECUTION RESULTS (pssgen) | AB1: GROUP E — CLOSURE (engineer) | AF1: GROUP F — PROGRAM CONTEXT (set once per release)
A2: Req_ID | B2: Family | C2: Type | D2: Statement | E2: Source_Doc | F2: Source_Section | G2: Verification_Method | H2: Covered_By | I2: Stimulus_Strategy | J2: Boundary_Notes | K2: Disposition | L2: Waiver_Rationale | M2: Risk_Acceptance | N2: Verification_Category | O2: Applicability | P2: Test_Name | Q2: HDL_Source | R2: Sim_Mode | S2: RTL_Status | T2: RTL_Run_Date | U2: RTL_Commit | V2: RTL_Evidence | W2: Gate_Status | X2: Gate_Evidence | Y2: Config_Set | Z2: Tool_Version | AA2: Anomaly_ID | AB2: Overall_Status | AC2: Closure_Author | AD2: Closure_Date | AE2: Closure_Notes | AF2: IP_Version | AG2: Target_Device | AH2: Spec_Revision
A3: [BLOCK-FAM-NNN] | B3: FAM | C3: functional | D3: The [block] shall [behavior] when [condition]. | E3: SPEC-RS-001 | F3: §N.N | G3: test | H3: COV-NNN | I3: Describe how the COV item exercises this requirement. | J3: Corner cases, boundary values. | K3: GENERATED | L3: (populate only when WAIVED) | M3: (populate only when WAIVED) | N3: Functional | O3: ALL | P3: block_feature_test | Q3: vhdl/block.vhd | R3: RTL | S3: NOT_RUN | W3: NOT_RUN | Y3: G_FIFO_DEPTH=16, G_DEFAULT_BAUD=115200, G_CLK_FREQ_HZ=100000000 | Z3: Vivado 2024.1 / Questa 23.2 | AB3: =IF(K3="WAIVED","WAIVED",IF(H3="","OPEN",IF(S3="BLOCKED","BLOCKED",IF(S3="FAIL","FAILING",IF(S3="PASS",IF(AA3<>"","AT_RISK",IF(AC3<>"","CLOSED","PASSING")),"COVERED"))))) | AF3: 0.0.0
A4: UART-PAR-001 | B4: PAR | C4: parametric | D4: The Buffered AXI-Lite UART shall implement the four compile-time parameters defined in Table 3-2 with the VHDL names G_CLK_FREQ_HZ, G_DEFAULT_BAUD, G_FIFO_DEPTH, and G_TIMEOUT_DEFAULT, and the equivalent SystemVerilog names P_CLK_FREQ_HZ, P_DEFAULT_BAUD, P_FIFO_DEPTH, and P_TIMEOUT_DEFAULT, with the specified types, defaults, and valid ranges. | E4: BALU-RS-001 | F4: §3.4 | G4: inspection | H4: COV-017 | I4: Structural inspection: verify 8-bit data frames transmitted and received, AXI data width=32, address width sufficient, single-beat transactions only. | K4: GENERATED | N4: Parametric | O4: ALL | Q4: vhdl/buffered_axi_lite_uart.vhd | R4: RTL | S4: NOT_RUN | W4: NOT_RUN | AB4: =IF(K4="WAIVED","WAIVED",IF(H4="","OPEN",IF(S4="BLOCKED","BLOCKED",IF(S4="FAIL","FAILING",IF(S4="PASS",IF(AA4<>"","AT_RISK",IF(AC4<>"","CLOSED","PASSING")),"COVERED"))))) | AF4: 1.0.0 | AG4: ZUBoard 1CG / Basys 3 | AH4: BALU-RS-001 Rev 0.4
A5: UART-PAR-002 | B5: PAR | C5: parametric | D5: The Buffered AXI-Lite UART shall implement the FIFO depth parameter (G_FIFO_DEPTH in VHDL, P_FIFO_DEPTH in SystemVerilog) as a power of 2 in the range 8 to 256 inclusive. | E5: BALU-RS-001 | F5: §3.4 | G5: analysis | H5: COV-017 | I5: Structural inspection: verify 8-bit data frames transmitted and received, AXI data width=32, address width sufficient, single-beat transactions only. | K5: GENERATED | N5: Parametric | O5: ALL | Q5: vhdl/buffered_axi_lite_uart.vhd | R5: RTL | S5: NOT_RUN | W5: NOT_RUN | AB5: =IF(K5="WAIVED","WAIVED",IF(H5="","OPEN",IF(S5="BLOCKED","BLOCKED",IF(S5="FAIL","FAILING",IF(S5="PASS",IF(AA5<>"","AT_RISK",IF(AC5<>"","CLOSED","PASSING")),"COVERED"))))) | AF5: 1.0.0 | AG5: ZUBoard 1CG / Basys 3 | AH5: BALU-RS-001 Rev 0.4
A6: UART-PAR-003 | B6: PAR | C6: build-time | D6: The Buffered AXI-Lite UART shall produce an elaboration-time assertion failure with a descriptive message identifying the parameter name and violated constraint when any compile-time parameter is instantiated with a value outside its specified range. In VHDL the assertion severity shall be failure. In SystemVerilog $fatal shall be used. | E6: BALU-RS-001 | F6: §3.4 | G6: test | K6: WAIVED | L6: Elaboration-time assertion — $fatal fires before simulation begins. Requires a separate negative build test. Deferred to build-system test phase. | M6: MEDIUM | N6: Parametric | O6: ALL | Q6: vhdl/buffered_axi_lite_uart.vhd | R6: RTL | S6: NOT_RUN | W6: NOT_RUN | AB6: =IF(K6="WAIVED","WAIVED",IF(H6="","OPEN",IF(S6="BLOCKED","BLOCKED",IF(S6="FAIL","FAILING",IF(S6="PASS",IF(AA6<>"","AT_RISK",IF(AC6<>"","CLOSED","PASSING")),"COVERED"))))) | AF6: 1.0.0 | AG6: ZUBoard 1CG / Basys 3 | AH6: BALU-RS-001 Rev 0.4
A7: UART-PAR-004 | B7: PAR | C7: parametric | D7: The Buffered AXI-Lite UART shall accept a system clock frequency parameter (G_CLK_FREQ_HZ / P_CLK_FREQ_HZ) in the range 1,000,000 to 1,000,000,000 inclusive specifying the system clock frequency in Hz. | E7: BALU-RS-001 | F7: §3.4 | G7: analysis | H7: COV-001 | I7: NCO tuning word sweep at 12 values from minimum (0x00000001) to maximum (0xFFFFFFFF) including all standard baud rates. | K7: GENERATED | N7: Parametric | O7: ALL | Q7: vhdl/buffered_axi_lite_uart.vhd | R7: RTL | S7: NOT_RUN | W7: NOT_RUN | AB7: =IF(K7="WAIVED","WAIVED",IF(H7="","OPEN",IF(S7="BLOCKED","BLOCKED",IF(S7="FAIL","FAILING",IF(S7="PASS",IF(AA7<>"","AT_RISK",IF(AC7<>"","CLOSED","PASSING")),"COVERED"))))) | AF7: 1.0.0 | AG7: ZUBoard 1CG / Basys 3 | AH7: BALU-RS-001 Rev 0.4
A8: UART-PAR-005 | B8: PAR | C8: parametric | D8: The Buffered AXI-Lite UART shall accept a default baud rate parameter (G_DEFAULT_BAUD / P_DEFAULT_BAUD) in the range 1 to CLK_FREQ_HZ / 2 inclusive specifying the target baud rate at reset. | E8: BALU-RS-001 | F8: §3.4 | G8: analysis | H8: COV-001 | I8: NCO tuning word sweep at 12 values from minimum (0x00000001) to maximum (0xFFFFFFFF) including all standard baud rates. | K8: GENERATED | N8: Parametric | O8: ALL | Q8: vhdl/buffered_axi_lite_uart.vhd | R8: RTL | S8: NOT_RUN | W8: NOT_RUN | AB8: =IF(K8="WAIVED","WAIVED",IF(H8="","OPEN",IF(S8="BLOCKED","BLOCKED",IF(S8="FAIL","FAILING",IF(S8="PASS",IF(AA8<>"","AT_RISK",IF(AC8<>"","CLOSED","PASSING")),"COVERED"))))) | AF8: 1.0.0 | AG8: ZUBoard 1CG / Basys 3 | AH8: BALU-RS-001 Rev 0.4
A9: UART-PAR-006 | B9: PAR | C9: parametric | D9: The Buffered AXI-Lite UART shall accept a timeout default parameter (G_TIMEOUT_DEFAULT / P_TIMEOUT_DEFAULT) in the range 0 to 65535 inclusive specifying the TIMEOUT_VAL register reset value in baud clock ticks. A value of 0 disables the receive timeout at reset. | E9: BALU-RS-001 | F9: §3.4 | G9: analysis | H9: COV-006 | I9: TIMEOUT_VAL set to 0x0000, 0x0001, G_TIMEOUT_DEFAULT, 0xFFFE, and 0xFFFF; idle receiver until timeout fires for each non-zero value. | K9: GENERATED | N9: Parametric | O9: ALL | Q9: vhdl/buffered_axi_lite_uart.vhd | R9: RTL | S9: NOT_RUN | W9: NOT_RUN | AB9: =IF(K9="WAIVED","WAIVED",IF(H9="","OPEN",IF(S9="BLOCKED","BLOCKED",IF(S9="FAIL","FAILING",IF(S9="PASS",IF(AA9<>"","AT_RISK",IF(AC9<>"","CLOSED","PASSING")),"COVERED"))))) | AF9: 1.0.0 | AG9: ZUBoard 1CG / Basys 3 | AH9: BALU-RS-001 Rev 0.4
A10: UART-PAR-007 | B10: PAR | C10: parametric | D10: The Buffered AXI-Lite UART shall compute the BAUD_TUNING register reset value (C_BAUD_TUNING_RESET in VHDL, LP_BAUD_TUNING_RESET in SystemVerilog) as round(DEFAULT_BAUD × 2³² / CLK_FREQ_HZ) using round-to-nearest arithmetic. Truncation shall not be used for this computation. | E10: BALU-RS-001 | F10: §3.4 | G10: analysis | H10: COV-001, COV-015 | I10: NCO tuning word sweep at 12 values from minimum (0x00000001) to maximum (0xFFFFFFFF) including all standard baud rates. | K10: GENERATED | N10: Parametric | O10: ALL | Q10: vhdl/buffered_axi_lite_uart.vhd | R10: RTL | S10: NOT_RUN | W10: NOT_RUN | AB10: =IF(K10="WAIVED","WAIVED",IF(H10="","OPEN",IF(S10="BLOCKED","BLOCKED",IF(S10="FAIL","FAILING",IF(S10="PASS",IF(AA10<>"","AT_RISK",IF(AC10<>"","CLOSED","PASSING")),"COVERED"))))) | AF10: 1.0.0 | AG10: ZUBoard 1CG / Basys 3 | AH10: BALU-RS-001 Rev 0.4
A11: UART-PAR-008 | B11: PAR | C11: parametric | D11: The Buffered AXI-Lite UART shall set the FIFO_CTRL register reset value (C_FIFO_THRESH_RESET in VHDL, LP_FIFO_THRESH_RESET in SystemVerilog) such that TX_THRESH and RX_THRESH each equal FIFO_DEPTH / 2, providing threshold interrupts at half-full by default. | E11: BALU-RS-001 | F11: §3.4 | G11: test | H11: COV-015 | I11: Assert then deassert reset; read all 12 registers and compare each field to the reset value specified in Table 8-x. | K11: GENERATED | N11: Parametric | O11: ALL | Q11: vhdl/buffered_axi_lite_uart.vhd | R11: RTL | S11: NOT_RUN | W11: NOT_RUN | AB11: =IF(K11="WAIVED","WAIVED",IF(H11="","OPEN",IF(S11="BLOCKED","BLOCKED",IF(S11="FAIL","FAILING",IF(S11="PASS",IF(AA11<>"","AT_RISK",IF(AC11<>"","CLOSED","PASSING")),"COVERED"))))) | AF11: 1.0.0 | AG11: ZUBoard 1CG / Basys 3 | AH11: BALU-RS-001 Rev 0.4
A12: UART-PAR-009 | B12: PAR | C12: parametric | D12: The Buffered AXI-Lite UART shall size the FIFO_STATUS TX_LEVEL and RX_LEVEL fields as 8-bit unsigned integers capable of representing occupancy values 0 to FIFO_DEPTH inclusive for all supported values of FIFO_DEPTH. | E12: BALU-RS-001 | F12: §3.4 | G12: test | H12: COV-017 | I12: Structural inspection: verify 8-bit data frames transmitted and received, AXI data width=32, address width sufficient, single-beat transactions only. | K12: GENERATED | N12: Parametric | O12: ALL | Q12: vhdl/buffered_axi_lite_uart.vhd | R12: RTL | S12: NOT_RUN | W12: NOT_RUN | AB12: =IF(K12="WAIVED","WAIVED",IF(H12="","OPEN",IF(S12="BLOCKED","BLOCKED",IF(S12="FAIL","FAILING",IF(S12="PASS",IF(AA12<>"","AT_RISK",IF(AC12<>"","CLOSED","PASSING")),"COVERED"))))) | AF12: 1.0.0 | AG12: ZUBoard 1CG / Basys 3 | AH12: BALU-RS-001 Rev 0.4
A13: UART-IF-001 | B13: IF | C13: functional | D13: The Buffered AXI-Lite UART shall implement an AXI-Lite slave interface compliant with the ARM AMBA AXI4-Lite specification. | E13: BALU-RS-001 | F13: §6.1 | G13: test | H13: COV-017 | I13: Structural inspection: verify 8-bit data frames transmitted and received, AXI data width=32, address width sufficient, single-beat transactions only. | K13: GENERATED | N13: Protocol_Compliance | O13: ALL | Q13: vhdl/buffered_axi_lite_uart.vhd | R13: RTL | S13: NOT_RUN | W13: NOT_RUN | AB13: =IF(K13="WAIVED","WAIVED",IF(H13="","OPEN",IF(S13="BLOCKED","BLOCKED",IF(S13="FAIL","FAILING",IF(S13="PASS",IF(AA13<>"","AT_RISK",IF(AC13<>"","CLOSED","PASSING")),"COVERED"))))) | AF13: 1.0.0 | AG13: ZUBoard 1CG / Basys 3 | AH13: BALU-RS-001 Rev 0.4
A14: UART-IF-002 | B14: IF | C14: functional | D14: The Buffered AXI-Lite UART shall provide an AXI-Lite data width of 32 bits. | E14: BALU-RS-001 | F14: §6.1 | G14: inspection | H14: COV-017 | I14: Structural inspection: verify 8-bit data frames transmitted and received, AXI data width=32, address width sufficient, single-beat transactions only. | K14: GENERATED | N14: Protocol_Compliance | O14: ALL | Q14: vhdl/buffered_axi_lite_uart.vhd | R14: RTL | S14: NOT_RUN | W14: NOT_RUN | AB14: =IF(K14="WAIVED","WAIVED",IF(H14="","OPEN",IF(S14="BLOCKED","BLOCKED",IF(S14="FAIL","FAILING",IF(S14="PASS",IF(AA14<>"","AT_RISK",IF(AC14<>"","CLOSED","PASSING")),"COVERED"))))) | AF14: 1.0.0 | AG14: ZUBoard 1CG / Basys 3 | AH14: BALU-RS-001 Rev 0.4
A15: UART-IF-003 | B15: IF | C15: functional | D15: The Buffered AXI-Lite UART shall provide an AXI-Lite address width sufficient to address all defined register offsets within the peripheral address space. | E15: BALU-RS-001 | F15: §6.1 | G15: inspection | H15: COV-017 | I15: Structural inspection: verify 8-bit data frames transmitted and received, AXI data width=32, address width sufficient, single-beat transactions only. | K15: GENERATED | N15: Protocol_Compliance | O15: ALL | Q15: vhdl/buffered_axi_lite_uart.vhd | R15: RTL | S15: NOT_RUN | W15: NOT_RUN | AB15: =IF(K15="WAIVED","WAIVED",IF(H15="","OPEN",IF(S15="BLOCKED","BLOCKED",IF(S15="FAIL","FAILING",IF(S15="PASS",IF(AA15<>"","AT_RISK",IF(AC15<>"","CLOSED","PASSING")),"COVERED"))))) | AF15: 1.0.0 | AG15: ZUBoard 1CG / Basys 3 | AH15: BALU-RS-001 Rev 0.4
A16: UART-IF-004 | B16: IF | C16: functional | D16: The Buffered AXI-Lite UART shall accept single-beat AXI-Lite read and write transactions only. Burst transactions shall not be supported. | E16: BALU-RS-001 | F16: §6.1 | G16: test | H16: COV-017 | I16: Structural inspection: verify 8-bit data frames transmitted and received, AXI data width=32, address width sufficient, single-beat transactions only. | K16: GENERATED | N16: Protocol_Compliance | O16: ALL | Q16: vhdl/buffered_axi_lite_uart.vhd | R16: RTL | S16: NOT_RUN | W16: NOT_RUN | AB16: =IF(K16="WAIVED","WAIVED",IF(H16="","OPEN",IF(S16="BLOCKED","BLOCKED",IF(S16="FAIL","FAILING",IF(S16="PASS",IF(AA16<>"","AT_RISK",IF(AC16<>"","CLOSED","PASSING")),"COVERED"))))) | AF16: 1.0.0 | AG16: ZUBoard 1CG / Basys 3 | AH16: BALU-RS-001 Rev 0.4
A17: UART-IF-005 | B17: IF | C17: functional | D17: The Buffered AXI-Lite UART shall accept AWVALID and WVALID arriving in any order on the write address and write data channels, and shall not complete the write transaction until both have been accepted. | E17: BALU-RS-001 | F17: §6.1 | G17: test | H17: COV-012 | I17: Issue AXI write with AWVALID first then WVALID, then repeat with WVALID first then AWVALID; verify correct response in both orderings. | K17: GENERATED | N17: Protocol_Compliance | O17: ALL | Q17: vhdl/buffered_axi_lite_uart.vhd | R17: RTL | S17: NOT_RUN | W17: NOT_RUN | AB17: =IF(K17="WAIVED","WAIVED",IF(H17="","OPEN",IF(S17="BLOCKED","BLOCKED",IF(S17="FAIL","FAILING",IF(S17="PASS",IF(AA17<>"","AT_RISK",IF(AC17<>"","CLOSED","PASSING")),"COVERED"))))) | AF17: 1.0.0 | AG17: ZUBoard 1CG / Basys 3 | AH17: BALU-RS-001 Rev 0.4
A18: UART-IF-006 | B18: IF | C18: functional | D18: The Buffered AXI-Lite UART shall return OKAY (2'b00) on BRESP for all successful write transactions. | E18: BALU-RS-001 | F18: §6.1 | G18: test | H18: COV-010 | I18: AXI write to valid register offset (OKAY expected) and to undefined offset 0x30 (SLVERR expected); capture BRESP each time. | K18: GENERATED | N18: Protocol_Compliance | O18: ALL | Q18: vhdl/buffered_axi_lite_uart.vhd | R18: RTL | S18: NOT_RUN | W18: NOT_RUN | AB18: =IF(K18="WAIVED","WAIVED",IF(H18="","OPEN",IF(S18="BLOCKED","BLOCKED",IF(S18="FAIL","FAILING",IF(S18="PASS",IF(AA18<>"","AT_RISK",IF(AC18<>"","CLOSED","PASSING")),"COVERED"))))) | AF18: 1.0.0 | AG18: ZUBoard 1CG / Basys 3 | AH18: BALU-RS-001 Rev 0.4
... A35: UART-BR-003 | B35: BR | C35: functional | D35: The Buffered AXI-Lite UART shall reset BAUD_TUNING to C_BAUD_TUNING_RESET = round(G_DEFAULT_BAUD × 2³² / G_CLK_FREQ_HZ). At default values of G_DEFAULT_BAUD = 115,200 and G_CLK_FREQ_HZ = 100,000,000 this yields 0x004FA6D5 with error less than 0.0001%. | E35: BALU-RS-001 | F35: §7.2 | G35: test | H35: COV-001 | I35: NCO tuning word sweep at 12 values from minimum (0x00000001) to maximum (0xFFFFFFFF) including all standard baud rates. | K35: GENERATED | N35: Functional | O35: ALL | Q35: vhdl/buffered_axi_lite_uart.vhd | R35: RTL | S35: NOT_RUN | W35: NOT_RUN | AB35: =IF(K35="WAIVED","WAIVED",IF(H35="","OPEN",IF(S35="BLOCKED","BLOCKED",IF(S35="FAIL","FAILING",IF(S35="PASS",IF(AA35<>"","AT_RISK",IF(AC35<>"","CLOSED","PASSING")),"COVERED"))))) | AF35: 1.0.0 | AG35: ZUBoard 1CG / Basys 3 | AH35: BALU-RS-001 Rev 0.4
A36: UART-BR-004 | B36: BR | C36: functional | D36: The Buffered AXI-Lite UART shall silently ignore writes to BAUD_TUNING while UART_EN is asserted, leaving the accumulator tuning word unchanged. | E36: BALU-RS-001 | F36: §7.2 | G36: test | K36: GENERATED | N36: Functional | O36: ALL | Q36: vhdl/buffered_axi_lite_uart.vhd | R36: RTL | S36: NOT_RUN | W36: NOT_RUN | AB36: =IF(K36="WAIVED","WAIVED",IF(H36="","OPEN",IF(S36="BLOCKED","BLOCKED",IF(S36="FAIL","FAILING",IF(S36="PASS",IF(AA36<>"","AT_RISK",IF(AC36<>"","CLOSED","PASSING")),"COVERED"))))) | AF36: 1.0.0 | AG36: ZUBoard 1CG / Basys 3 | AH36: BALU-RS-001 Rev 0.4
A37: UART-BR-005 | B37: BR | C37: functional | D37: The Buffered AXI-Lite UART shall disable baud clock generation when BAUD_TUNING = 0x00000000. No baud clock pulses shall be produced and no UART framing activity shall occur. | E37: BALU-RS-001 | F37: §7.2 | G37: test | H37: COV-001 | I37: NCO tuning word sweep at 12 values from minimum (0x00000001) to maximum (0xFFFFFFFF) including all standard baud rates. | K37: GENERATED | N37: Functional | O37: ALL | Q37: vhdl/buffered_axi_lite_uart.vhd | R37: RTL | S37: NOT_RUN | W37: NOT_RUN | AB37: =IF(K37="WAIVED","WAIVED",IF(H37="","OPEN",IF(S37="BLOCKED","BLOCKED",IF(S37="FAIL","FAILING",IF(S37="PASS",IF(AA37<>"","AT_RISK",IF(AC37<>"","CLOSED","PASSING")),"COVERED"))))) | AF37: 1.0.0 | AG37: ZUBoard 1CG / Basys 3 | AH37: BALU-RS-001 Rev 0.4
A38: UART-BR-006 | B38: BR | C38: functional | D38: The Buffered AXI-Lite UART shall produce the minimum supported baud rate without undefined behavior when BAUD_TUNING = 0x00000001. | E38: BALU-RS-001 | F38: §7.2 | G38: test | H38: COV-001 | I38: NCO tuning word sweep at 12 values from minimum (0x00000001) to maximum (0xFFFFFFFF) including all standard baud rates. | K38: GENERATED | N38: Functional | O38: ALL | Q38: vhdl/buffered_axi_lite_uart.vhd | R38: RTL | S38: NOT_RUN | W38: NOT_RUN | AB38: =IF(K38="WAIVED","WAIVED",IF(H38="","OPEN",IF(S38="BLOCKED","BLOCKED",IF(S38="FAIL","FAILING",IF(S38="PASS",IF(AA38<>"","AT_RISK",IF(AC38<>"","CLOSED","PASSING")),"COVERED"))))) | AF38: 1.0.0 | AG38: ZUBoard 1CG / Basys 3 | AH38: BALU-RS-001 Rev 0.4
A39: UART-FF-001 | B39: FF | C39: functional | D39: The Buffered AXI-Lite UART shall support 8 data bits per frame. | E39: BALU-RS-001 | F39: §7.3 | G39: test | H39: COV-017 | I39: Structural inspection: verify 8-bit data frames transmitted and received, AXI data width=32, address width sufficient, single-beat transactions only. | K39: GENERATED | N39: Functional | O39: ALL | Q39: vhdl/buffered_axi_lite_uart.vhd | R39: RTL | S39: NOT_RUN | W39: NOT_RUN | AB39: =IF(K39="WAIVED","WAIVED",IF(H39="","OPEN",IF(S39="BLOCKED","BLOCKED",IF(S39="FAIL","FAILING",IF(S39="PASS",IF(AA39<>"","AT_RISK",IF(AC39<>"","CLOSED","PASSING")),"COVERED"))))) | AF39: 1.0.0 | AG39: ZUBoard 1CG / Basys 3 | AH39: BALU-RS-001 Rev 0.4
A40: UART-FF-002 | B40: FF | C40: functional | D40: The Buffered AXI-Lite UART shall append one stop bit per transmitted frame when STOP_BITS = 0. | E40: BALU-RS-001 | F40: §7.3 | G40: test | H40: COV-003 | I40: Both stop bit configurations (1 and 2 stop bits) exercised in LOOP_EN loopback with frame integrity check. | K40: GENERATED | N40: Functional | O40: ALL | Q40: vhdl/buffered_axi_lite_uart.vhd | R40: RTL | S40: NOT_RUN | W40: NOT_RUN | AB40: =IF(K40="WAIVED","WAIVED",IF(H40="","OPEN",IF(S40="BLOCKED","BLOCKED",IF(S40="FAIL","FAILING",IF(S40="PASS",IF(AA40<>"","AT_RISK",IF(AC40<>"","CLOSED","PASSING")),"COVERED"))))) | AF40: 1.0.0 | AG40: ZUBoard 1CG / Basys 3 | AH40: BALU-RS-001 Rev 0.4
A41: UART-FF-003 | B41: FF | C41: functional | D41: The Buffered AXI-Lite UART shall append two stop bits per transmitted frame when STOP_BITS = 1. | E41: BALU-RS-001 | F41: §7.3 | G41: test | H41: COV-003 | I41: Both stop bit configurations (1 and 2 stop bits) exercised in LOOP_EN loopback with frame integrity check. | K41: GENERATED | N41: Functional | O41: ALL | Q41: vhdl/buffered_axi_lite_uart.vhd | R41: RTL | S41: NOT_RUN | W41: NOT_RUN | AB41: =IF(K41="WAIVED","WAIVED",IF(H41="","OPEN",IF(S41="BLOCKED","BLOCKED",IF(S41="FAIL","FAILING",IF(S41="PASS",IF(AA41<>"","AT_RISK",IF(AC41<>"","CLOSED","PASSING")),"COVERED"))))) | AF41: 1.0.0 | AG41: ZUBoard 1CG / Basys 3 | AH41: BALU-RS-001 Rev 0.4
A42: UART-FF-004 | B42: FF | C42: functional | D42: The Buffered AXI-Lite UART shall accept frames with one stop bit on receive regardless of the STOP_BITS setting. | E42: BALU-RS-001 | F42: §7.3 | G42: test | H42: COV-003 | I42: Both stop bit configurations (1 and 2 stop bits) exercised in LOOP_EN loopback with frame integrity check. | K42: GENERATED | N42: Functional | O42: ALL | Q42: vhdl/buffered_axi_lite_uart.vhd | R42: RTL | S42: NOT_RUN | W42: NOT_RUN | AB42: =IF(K42="WAIVED","WAIVED",IF(H42="","OPEN",IF(S42="BLOCKED","BLOCKED",IF(S42="FAIL","FAILING",IF(S42="PASS",IF(AA42<>"","AT_RISK",IF(AC42<>"","CLOSED","PASSING")),"COVERED"))))) | AF42: 1.0.0 | AG42: ZUBoard 1CG / Basys 3 | AH42: BALU-RS-001 Rev 0.4
A43: UART-FF-005 | B43: FF | C43: functional | D43: The Buffered AXI-Lite UART shall transmit and accept frames with no parity bit when PARITY = 2'b00. | E43: BALU-RS-001 | F43: §7.3 | G43: test | H43: COV-002 | I43: All four parity modes (00/01/10/11) exercised independently in LOOP_EN loopback; inject parity error bit for odd and even modes. | K43: GENERATED | N43: Functional | O43: ALL | Q43: vhdl/buffered_axi_lite_uart.vhd | R43: RTL | S43: NOT_RUN | W43: NOT_RUN | AB43: =IF(K43="WAIVED","WAIVED",IF(H43="","OPEN",IF(S43="BLOCKED","BLOCKED",IF(S43="FAIL","FAILING",IF(S43="PASS",IF(AA43<>"","AT_RISK",IF(AC43<>"","CLOSED","PASSING")),"COVERED"))))) | AF43: 1.0.0 | AG43: ZUBoard 1CG / Basys 3 | AH43: BALU-RS-001 Rev 0.4
A44: UART-FF-006 | B44: FF | C44: functional | D44: The Buffered AXI-Lite UART shall generate and verify odd parity on every frame when PARITY = 2'b01. A parity mismatch shall set PARITY_ERR in STATUS and INT_STATUS. | E44: BALU-RS-001 | F44: §7.3 | G44: test | H44: COV-002 | I44: All four parity modes (00/01/10/11) exercised independently in LOOP_EN loopback; inject parity error bit for odd and even modes. | K44: GENERATED | N44: Functional | O44: ALL | Q44: vhdl/buffered_axi_lite_uart.vhd | R44: RTL | S44: NOT_RUN | W44: NOT_RUN | AB44: =IF(K44="WAIVED","WAIVED",IF(H44="","OPEN",IF(S44="BLOCKED","BLOCKED",IF(S44="FAIL","FAILING",IF(S44="PASS",IF(AA44<>"","AT_RISK",IF(AC44<>"","CLOSED","PASSING")),"COVERED"))))) | AF44: 1.0.0 | AG44: ZUBoard 1CG / Basys 3 | AH44: BALU-RS-001 Rev 0.4
A45: UART-FF-007 | B45: FF | C45: functional | D45: The Buffered AXI-Lite UART shall generate and verify even parity on every frame when PARITY = 2'b10. A parity mismatch shall set PARITY_ERR in STATUS and INT_STATUS. | E45: BALU-RS-001 | F45: §7.3 | G45: test | H45: COV-002 | I45: All four parity modes (00/01/10/11) exercised independently in LOOP_EN loopback; inject parity error bit for odd and even modes. | K45: GENERATED | N45: Functional | O45: ALL | Q45: vhdl/buffered_axi_lite_uart.vhd | R45: RTL | S45: NOT_RUN | W45: NOT_RUN | AB45: =IF(K45="WAIVED","WAIVED",IF(H45="","OPEN",IF(S45="BLOCKED","BLOCKED",IF(S45="FAIL","FAILING",IF(S45="PASS",IF(AA45<>"","AT_RISK",IF(AC45<>"","CLOSED","PASSING")),"COVERED"))))) | AF45: 1.0.0 | AG45: ZUBoard 1CG / Basys 3 | AH45: BALU-RS-001 Rev 0.4
A46: UART-FF-008 | B46: FF | C46: functional | D46: The Buffered AXI-Lite UART shall assert the parity bit in every transmitted frame when PARITY = 2'b11 (mark parity). On receive, a mark parity bit of logic 0 shall set PARITY_ERR in STATUS and INT_STATUS, as this indicates a line error or sender misconfiguration. This check is retained as a diagnostic in noise-sensitive environments where silent corruption is unacceptable. | E46: BALU-RS-001 | F46: §7.3 | G46: test | H46: COV-002 | I46: All four parity modes (00/01/10/11) exercised independently in LOOP_EN loopback; inject parity error bit for odd and even modes. | K46: GENERATED | N46: Functional | O46: ALL | Q46: vhdl/buffered_axi_lite_uart.vhd | R46: RTL | S46: NOT_RUN | W46: NOT_RUN | AB46: =IF(K46="WAIVED","WAIVED",IF(H46="","OPEN",IF(S46="BLOCKED","BLOCKED",IF(S46="FAIL","FAILING",IF(S46="PASS",IF(AA46<>"","AT_RISK",IF(AC46<>"","CLOSED","PASSING")),"COVERED"))))) | AF46: 1.0.0 | AG46: ZUBoard 1CG / Basys 3 | AH46: BALU-RS-001 Rev 0.4
A47: UART-FF-009 | B47: FF | C47: functional | D47: The Buffered AXI-Lite UART shall set PARITY_ERR in STATUS when a parity error is detected by the receiver. This flag shall remain set until the STATUS register is read. | E47: BALU-RS-001 | F47: §7.3 | G47: test | H47: COV-002 | I47: All four parity modes (00/01/10/11) exercised independently in LOOP_EN loopback; inject parity error bit for odd and even modes. | K47: GENERATED | N47: Functional | O47: ALL | Q47: vhdl/buffered_axi_lite_uart.vhd | R47: RTL | S47: NOT_RUN | W47: NOT_RUN | AB47: =IF(K47="WAIVED","WAIVED",IF(H47="","OPEN",IF(S47="BLOCKED","BLOCKED",IF(S47="FAIL","FAILING",IF(S47="PASS",IF(AA47<>"","AT_RISK",IF(AC47<>"","CLOSED","PASSING")),"COVERED"))))) | AF47: 1.0.0 | AG47: ZUBoard 1CG / Basys 3 | AH47: BALU-RS-001 Rev 0.4
A48: UART-FIFO-001 | B48: FIFO | C48: functional | D48: The Buffered AXI-Lite UART shall implement separate TX and RX FIFOs each with a depth of G_FIFO_DEPTH entries of 8 bits. | E48: BALU-RS-001 | F48: §7.4 | G48: inspection | H48: COV-017 | I48: Structural inspection: verify 8-bit data frames transmitted and received, AXI data width=32, address width sufficient, single-beat transactions only. | K48: GENERATED | N48: Functional | O48: ALL | Q48: vhdl/buffered_axi_lite_uart.vhd | R48: RTL | S48: NOT_RUN | W48: NOT_RUN | AB48: =IF(K48="WAIVED","WAIVED",IF(H48="","OPEN",IF(S48="BLOCKED","BLOCKED",IF(S48="FAIL","FAILING",IF(S48="PASS",IF(AA48<>"","AT_RISK",IF(AC48<>"","CLOSED","PASSING")),"COVERED"))))) | AF48: 1.0.0 | AG48: ZUBoard 1CG / Basys 3 | AH48: BALU-RS-001 Rev 0.4
... A134: UART-RST-006 | B134: RST | C134: functional | D134: The Buffered AXI-Lite UART shall reset BAUD_TUNING to C_BAUD_TUNING_RESET per UART-BR-003. | E134: BALU-RS-001 | F134: §9 | G134: test | H134: COV-015 | I134: Assert then deassert reset; read all 12 registers and compare each field to the reset value specified in Table 8-x. | K134: GENERATED | N134: Reset | O134: ALL | Q134: vhdl/buffered_axi_lite_uart.vhd | R134: RTL | S134: NOT_RUN | W134: NOT_RUN | AB134: =IF(K134="WAIVED","WAIVED",IF(H134="","OPEN",IF(S134="BLOCKED","BLOCKED",IF(S134="FAIL","FAILING",IF(S134="PASS",IF(AA134<>"","AT_RISK",IF(AC134<>"","CLOSED","PASSING")),"COVERED"))))) | AF134: 1.0.0 | AG134: ZUBoard 1CG / Basys 3 | AH134: BALU-RS-001 Rev 0.4
A135: UART-VER-001 | B135: VER | C135: infrastructure | D135: UVM RAL model for all 12 registers | E135: BALU-RS-001 | F135: §11 | G135: inspection | K135: WAIVED | L135: Verification infrastructure requirement. Describes the UVM RAL model artifact, not a testable behavior. Closed by inspection when the RAL model is committed. | M135: LOW | N135: Infrastructure | O135: ALL | Q135: vhdl/buffered_axi_lite_uart.vhd | R135: RTL | S135: NOT_RUN | W135: NOT_RUN | AB135: =IF(K135="WAIVED","WAIVED",IF(H135="","OPEN",IF(S135="BLOCKED","BLOCKED",IF(S135="FAIL","FAILING",IF(S135="PASS",IF(AA135<>"","AT_RISK",IF(AC135<>"","CLOSED","PASSING")),"COVERED"))))) | AF135: 1.0.0 | AG135: ZUBoard 1CG / Basys 3 | AH135: BALU-RS-001 Rev 0.4
A136: UART-VER-002 | B136: VER | C136: infrastructure | D136: Reset value test for all registers | E136: BALU-RS-001 | F136: §11 | G136: test | H136: COV-015 | I136: Assert then deassert reset; read all 12 registers and compare each field to the reset value specified in Table 8-x. | K136: GENERATED | N136: Infrastructure | O136: ALL | Q136: vhdl/buffered_axi_lite_uart.vhd | R136: RTL | S136: NOT_RUN | W136: NOT_RUN | AB136: =IF(K136="WAIVED","WAIVED",IF(H136="","OPEN",IF(S136="BLOCKED","BLOCKED",IF(S136="FAIL","FAILING",IF(S136="PASS",IF(AA136<>"","AT_RISK",IF(AC136<>"","CLOSED","PASSING")),"COVERED"))))) | AF136: 1.0.0 | AG136: ZUBoard 1CG / Basys 3 | AH136: BALU-RS-001 Rev 0.4
A137: UART-VER-003 | B137: VER | C137: infrastructure | D137: SCRATCH walking-ones connectivity test | E137: BALU-RS-001 | F137: §11 | G137: test | H137: COV-014 | I137: Write walking-ones (0x00000001 through 0x80000000), all-ones (0xFFFFFFFF), and all-zeros (0x00000000) to SCRATCH; read back and verify each value. | K137: GENERATED | N137: Infrastructure | O137: ALL | Q137: vhdl/buffered_axi_lite_uart.vhd | R137: RTL | S137: NOT_RUN | W137: NOT_RUN | AB137: =IF(K137="WAIVED","WAIVED",IF(H137="","OPEN",IF(S137="BLOCKED","BLOCKED",IF(S137="FAIL","FAILING",IF(S137="PASS",IF(AA137<>"","AT_RISK",IF(AC137<>"","CLOSED","PASSING")),"COVERED"))))) | AF137: 1.0.0 | AG137: ZUBoard 1CG / Basys 3 | AH137: BALU-RS-001 Rev 0.4
A138: UART-VER-004 | B138: VER | C138: infrastructure | D138: All 8 interrupt sources independently | E138: BALU-RS-001 | F138: §11 | G138: test | H138: COV-007 | I138: Each of 8 interrupt sources set and cleared independently via directed stimulus; verify IRQ asserts and deasserts correctly for each bit. | K138: GENERATED | N138: Infrastructure | O138: ALL | Q138: vhdl/buffered_axi_lite_uart.vhd | R138: RTL | S138: NOT_RUN | W138: NOT_RUN | AB138: =IF(K138="WAIVED","WAIVED",IF(H138="","OPEN",IF(S138="BLOCKED","BLOCKED",IF(S138="FAIL","FAILING",IF(S138="PASS",IF(AA138<>"","AT_RISK",IF(AC138<>"","CLOSED","PASSING")),"COVERED"))))) | AF138: 1.0.0 | AG138: ZUBoard 1CG / Basys 3 | AH138: BALU-RS-001 Rev 0.4
A139: UART-VER-005 | B139: VER | C139: infrastructure | D139: OVERRUN + RX_FULL simultaneous | E139: BALU-RS-001 | F139: §11 | G139: test | H139: COV-008 | I139: Fill RX FIFO to capacity then transmit additional byte to force overrun; verify overrun byte discarded and FIFO content unchanged. | K139: GENERATED | N139: Infrastructure | O139: ALL | Q139: vhdl/buffered_axi_lite_uart.vhd | R139: RTL | S139: NOT_RUN | W139: NOT_RUN | AB139: =IF(K139="WAIVED","WAIVED",IF(H139="","OPEN",IF(S139="BLOCKED","BLOCKED",IF(S139="FAIL","FAILING",IF(S139="PASS",IF(AA139<>"","AT_RISK",IF(AC139<>"","CLOSED","PASSING")),"COVERED"))))) | AF139: 1.0.0 | AG139: ZUBoard 1CG / Basys 3 | AH139: BALU-RS-001 Rev 0.4
A140: UART-VER-006 | B140: VER | C140: infrastructure | D140: Both AXI write orderings exercised | E140: BALU-RS-001 | F140: §11 | G140: test | H140: COV-012 | I140: Issue AXI write with AWVALID first then WVALID, then repeat with WVALID first then AWVALID; verify correct response in both orderings. | K140: GENERATED | N140: Infrastructure | O140: ALL | Q140: vhdl/buffered_axi_lite_uart.vhd | R140: RTL | S140: NOT_RUN | W140: NOT_RUN | AB140: =IF(K140="WAIVED","WAIVED",IF(H140="","OPEN",IF(S140="BLOCKED","BLOCKED",IF(S140="FAIL","FAILING",IF(S140="PASS",IF(AA140<>"","AT_RISK",IF(AC140<>"","CLOSED","PASSING")),"COVERED"))))) | AF140: 1.0.0 | AG140: ZUBoard 1CG / Basys 3 | AH140: BALU-RS-001 Rev 0.4
A141: UART-VER-007 | B141: VER | C141: infrastructure | D141: BAUD_TUNING write while UART_EN=1 | E141: BALU-RS-001 | F141: §11 | G141: test | H141: COV-013 | I141: Assert UART_EN, write a new value to BAUD_TUNING, read back and verify original value unchanged; confirms silent-ignore while enabled. | K141: GENERATED | N141: Infrastructure | O141: ALL | Q141: vhdl/buffered_axi_lite_uart.vhd | R141: RTL | S141: NOT_RUN | W141: NOT_RUN | AB141: =IF(K141="WAIVED","WAIVED",IF(H141="","OPEN",IF(S141="BLOCKED","BLOCKED",IF(S141="FAIL","FAILING",IF(S141="PASS",IF(AA141<>"","AT_RISK",IF(AC141<>"","CLOSED","PASSING")),"COVERED"))))) | AF141: 1.0.0 | AG141: ZUBoard 1CG / Basys 3 | AH141: BALU-RS-001 Rev 0.4
...

Sheet Coverage_Goals
A2: ID | B2: Name | C2: Description | D2: Stimulus_Strategy | E2: Boundary_Values | F2: Linked_Requirements | G2: Status | H2: Coverage_Type | I2: Notes
A3: COV-001 | B3: BAUD_TUNING | C3: NCO tuning word sweep covering standard baud rates and boundary values. 12 values computed for G_CLK_FREQ_HZ = 100 MHz. | D3: NCO tuning word sweep at 12 values from minimum (0x00000001) to maximum (0xFFFFFFFF) including all standard baud rates. | E3: 0x00000001 (min), standard baud rates 9600-921600, 3/4 Mbaud, 0xFFFFFFFF (max) | F3: UART-BR-001, UART-BR-002, UART-BR-003, UART-BR-005, UART-BR-006, UART-PAR-004, UART-PAR-005, UART-PAR-007, UART-REG-026, UART-REG-027 | G3: PLANNED | H3: Functional
A4: COV-002 | B4: CTRL.PARITY | C4: All four parity modes (none/odd/even/mark) exercised independently in LOOP_EN loopback with parity error injection for odd and even modes. | D4: All four parity modes (00/01/10/11) exercised independently in LOOP_EN loopback; inject parity error bit for odd and even modes. | E4: 2'b00 (none), 2'b01 (odd+error inject), 2'b10 (even+error inject), 2'b11 (mark) | F4: UART-FF-005, UART-FF-006, UART-FF-007, UART-FF-008, UART-FF-009, UART-REG-009, UART-VER-009 | G4: PLANNED | H4: Functional
A5: COV-003 | B5: CTRL.STOP_BITS | C5: Both stop bit configurations (1 and 2 stop bits) exercised in loopback; receive accepts 1 stop bit in both modes. | D5: Both stop bit configurations (1 and 2 stop bits) exercised in LOOP_EN loopback with frame integrity check. | E5: 1'b0 (1 stop bit), 1'b1 (2 stop bits) | F5: UART-FF-002, UART-FF-003, UART-FF-004, UART-REG-010 | G5: PLANNED | H5: Functional
A6: COV-004 | B6: FIFO_STATUS.RX_LEVEL | C6: RX FIFO occupancy swept to key boundary values relative to RX_THRESH. G_FIFO_DEPTH used for instantiation independence. | D6: RX FIFO occupancy driven to 0, RX_THRESH-1, RX_THRESH, RX_THRESH+1, and G_FIFO_DEPTH to verify status flags and overrun discard. | E6: 0 (RX_EMPTY), RX_THRESH-1, RX_THRESH, RX_THRESH+1 (interrupt fires), G_FIFO_DEPTH (full/overrun) | F6: UART-FIFO-004, UART-FIFO-005, UART-FIFO-007, UART-FIFO-009, UART-REG-019, UART-REG-034 | G6: PLANNED | H6: Functional
A7: COV-005 | B7: FIFO_STATUS.TX_LEVEL | C7: TX FIFO occupancy swept to key boundary values. TX_THRESH fires when occupancy falls BELOW threshold (asymmetric vs RX — common RTL bug source). | D7: TX FIFO occupancy driven to 0, TX_THRESH-1, TX_THRESH, TX_THRESH+1, and G_FIFO_DEPTH to verify status flags and write-ignore behavior. | E7: 0 (TX_EMPTY), TX_THRESH-1, TX_THRESH, TX_THRESH+1 (interrupt fires), G_FIFO_DEPTH (full) | F7: UART-FIFO-002, UART-FIFO-003, UART-FIFO-006, UART-FIFO-008, UART-REG-016, UART-REG-017, UART-REG-033 | G7: PLANNED | H7: Functional
A8: COV-006 | B8: TIMEOUT_VAL | C8: Timeout counter exercised at disable boundary (0) and active values including reset default. G_TIMEOUT_DEFAULT used for instantiation independence. | D8: TIMEOUT_VAL set to 0x0000, 0x0001, G_TIMEOUT_DEFAULT, 0xFFFE, and 0xFFFF; idle receiver until timeout fires for each non-zero value. | E8: 0x0000 (disabled), 0x0001 (minimum active), G_TIMEOUT_DEFAULT (reset), 0xFFFE, 0xFFFF (maximum) | F8: UART-TO-001, UART-TO-002, UART-TO-003, UART-TO-004, UART-TO-005, UART-TO-006, UART-REG-035, UART-REG-036, UART-PAR-006, UART-VER-008 | G8: PLANNED | H8: Functional
A9: COV-007 | B9: INT_STATUS each_bit_independently | C9: Each of 8 interrupt sources set and cleared independently. Isolation before co-occurrence per NOTE-004. | D9: Each of 8 interrupt sources set and cleared independently via directed stimulus; verify IRQ asserts and deasserts correctly for each bit. | E9: Each of 8 bits: TIMEOUT, TX_THRESH, RX_THRESH, TX_EMPTY, RX_FULL, PARITY_ERR, FRAME_ERR, OVERRUN — set and W1C cleared independently | F9: UART-INT-001, UART-INT-002, UART-INT-003, UART-INT-004, UART-INT-005, UART-INT-006, UART-INT-007, UART-INT-008, UART-REG-037, UART-REG-039, UART-REG-040, UART-VER-004 | G9: PLANNED | H9: Functional
A10: COV-008 | B10: INT_STATUS.OVERRUN && INT_STATUS.RX_FULL | C10: RX overrun while FIFO full — critical co-occurrence likely to expose FIFO pointer corruption bugs. Verifies overrun byte discarded and FIFO content preserved. | D10: Fill RX FIFO to capacity then transmit additional byte to force overrun; verify overrun byte discarded and FIFO content unchanged. | E10: RX FIFO at exactly G_FIFO_DEPTH, then one additional received byte | F10: UART-FIFO-007, UART-INT-005, UART-INT-006, UART-REG-018, UART-REG-024, UART-VER-005, UART-VER-010 | G10: PLANNED | H10: Functional
A11: COV-009 | B11: INT_STATUS.TIMEOUT && INT_STATUS.RX_THRESH | C11: Timeout pending simultaneously with RX threshold. Verifies IRQ OR reduction logic handles multiple sources correctly. | D11: Set TIMEOUT_VAL non-zero, fill RX FIFO above RX_THRESH, then idle until timeout fires; verify both INT_STATUS.TIMEOUT and INT_STATUS.RX_THRESH set simultaneously. | E11: RX FIFO > RX_THRESH (threshold set), then idle until timeout fires while threshold remains set | F11: UART-TO-005, UART-INT-002, UART-INT-008, UART-REG-014 | G11: PLANNED | H11: Functional
A12: COV-010 | B12: AXI_BRESP | C12: Both OKAY (2'b00) and SLVERR (2'b10) response codes on write channel. SLVERR via undefined offset 0x30 per NOTE-005. | D12: AXI write to valid register offset (OKAY expected) and to undefined offset 0x30 (SLVERR expected); capture BRESP each time. | E12: Valid offset BRESP=OKAY, undefined offset 0x30 BRESP=SLVERR | F12: UART-IF-006, UART-IF-008, UART-REG-001 | G12: PLANNED | H12: Functional
A13: COV-011 | B13: AXI_RRESP | C13: Both OKAY (2'b00) and SLVERR (2'b10) response codes on read channel. SLVERR via undefined offset 0x30 per NOTE-005. | D13: AXI read from valid register offset (OKAY expected) and from undefined offset 0x30 (SLVERR expected); capture RRESP each time. | E13: Valid offset RRESP=OKAY, undefined offset 0x30 RRESP=SLVERR | F13: UART-IF-007, UART-IF-009, UART-REG-001 | G13: PLANNED | H13: Functional
A14: COV-012 | B14: AXI_WRITE_ORDER | C14: Both AWVALID-first and WVALID-first AXI write orderings exercised. Many AXI-Lite slave implementations incorrectly assume AWVALID first. | D14: Issue AXI write with AWVALID first then WVALID, then repeat with WVALID first then AWVALID; verify correct response in both orderings. | E14: AWVALID_FIRST ordering, WVALID_FIRST ordering | F14: UART-IF-005, UART-VER-006 | G14: PLANNED | H14: Functional
A15: COV-013 | B15: BAUD_TUNING_WRITE_WHILE_ENABLED | C15: Write to BAUD_TUNING while UART_EN=1. Verifies silent-ignore behavior. Gap demo coverage point — closes when UART-BR-004 added to .req [confirmed]. | D15: Assert UART_EN, write a new value to BAUD_TUNING, read back and verify original value unchanged; confirms silent-ignore while enabled. | E15: UART_EN=1, write new value, readback must equal original value | F15: UART-REG-028, UART-VER-007 | G15: PLANNED | H15: Functional | I15: Gap demo item — intentionally absent from initial .req cross-references
A16: COV-014 | B16: SCRATCH | C16: Walking-ones pattern plus all-zeros and all-ones written and read back. First test in every sequence per NOTE-006. | D16: Write walking-ones (0x00000001 through 0x80000000), all-ones (0xFFFFFFFF), and all-zeros (0x00000000) to SCRATCH; read back and verify each value. | E16: 0x00000001..0x80000000 (walking ones), 0x000000FF, 0xFFFFFFFF (all-ones), 0x00000000 (all-zeros) | F16: UART-REG-044, UART-REG-045, UART-REG-046, UART-VER-003 | G16: PLANNED | H16: Functional | I16: First test in all sequences per NOTE-006
A17: COV-015 | B17: RESET_VALUES | C17: All 12 registers read after reset deassertion and compared to spec-defined reset values from Table 8-x. | D17: Assert then deassert reset; read all 12 registers and compare each field to the reset value specified in Table 8-x. | E17: 12 register reset values per spec Table 8-x | F17: UART-RST-001, UART-RST-002, UART-RST-003, UART-RST-004, UART-RST-005, UART-RST-006, UART-REG-004, UART-REG-013, UART-REG-031, UART-REG-036, UART-REG-046, UART-PAR-007, UART-PAR-008, UART-VER-002 | G17: PLANNED | H17: Functional
A18: COV-016 | B18: UART_EN_CONTROL | C18: UART_EN, TX_EN, RX_EN, LOOP_EN control bit combinations verifying independent TX/RX path gating and loopback mode. | D18: Deassert UART_EN and verify TX/RX halt; then independently gate TX_EN and RX_EN with UART_EN=1 to verify path isolation; set LOOP_EN and verify loopback active. | E18: UART_EN=0 (halt), TX_EN=0 (TX off/RX active), RX_EN=0 (RX off/TX active), LOOP_EN=1 with UART_EN=1 | F18: UART-EN-001, UART-EN-002, UART-EN-003, UART-EN-004, UART-EN-005, UART-EN-006, UART-REG-005, UART-REG-006, UART-REG-007, UART-REG-008 | G18: PLANNED | H18: Functional
A19: COV-017 | B19: FRAME_STRUCTURAL | C19: Structural verification: 8-bit data frames, G_FIFO_DEPTH FIFO depth, 32-bit AXI data width, single-beat AXI transactions only. | D19: Structural inspection: verify 8-bit data frames transmitted and received, AXI data width=32, address width sufficient, single-beat transactions only. | E19: 8-bit frames; FIFO depth=G_FIFO_DEPTH; AXI data width=32; no burst transactions | F19: UART-FF-001, UART-FIFO-001, UART-IF-001, UART-IF-002, UART-IF-003, UART-IF-004, UART-IF-012, UART-IF-013, UART-IF-014, UART-PAR-001, UART-PAR-002, UART-PAR-009, UART-REG-032, UART-REG-033, UART-REG-034 | G19: PLANNED | H19: Structural
A20: COV-018 | B20: READONLY_IGNORE | C20: Write to each read-only register; read back and verify state unchanged. Covers STATUS, FIFO_STATUS, INT_STATUS, INT_CLEAR, TX_DATA reads, RX_DATA writes. | D20: Write to each read-only register (STATUS, FIFO_STATUS, INT_STATUS, INT_CLEAR, TX_DATA reads, RX_DATA writes); read back and verify state unchanged. | E20: Write all-ones to each RO register; compare pre- and post-write readback for each | F20: UART-IF-010, UART-IF-011, UART-REG-002, UART-REG-003, UART-REG-011, UART-REG-012, UART-REG-025, UART-REG-038, UART-REG-042, UART-REG-049, UART-REG-052 | G20: PLANNED | H20: Structural
A21: COV-019 | B21: INT_THRESH_FRAME | C21: TX/RX threshold interrupts, FRAME_ERR, and TIMEOUT interrupt enable gate exercised via directed stimulus targeting INT_ENABLE masking and INT_STATUS bit positions. | D21: Drive TX_THRESH and RX_THRESH interrupt conditions, inject FRAME_ERR via stop-bit corruption, enable TIMEOUT interrupt; verify each INT_STATUS bit controlled by INT_ENABLE gate. | E21: TX FIFO below TX_THRESH; RX FIFO above RX_THRESH; stop-bit corruption for FRAME_ERR; TIMEOUT with INT_ENABLE gates | F21: UART-INT-009, UART-INT-010, UART-INT-011, UART-INT-012, UART-INT-013, UART-TO-007, UART-REG-015, UART-REG-020, UART-REG-021, UART-REG-022, UART-REG-023, UART-REG-029, UART-REG-030, UART-REG-037, UART-REG-039, UART-REG-040, UART-REG-041, UART-REG-043, UART-REG-047, UART-REG-048, UART-REG-050, UART-REG-051 | G21: PLANNED | H21: Functional

Sheet Strategy_Notes
A1: STRATEGY NOTES — verification engineering decisions not captured in individual COV rows
A2: ID | B2: Topic | C2: Note | D2: Applies_To
A3: NOTE-001 | B3: Primary Stimulus Method | C3: Loopback mode (LOOP_EN) is the primary stimulus strategy for all frame format and parity coverage goals. External UART stimulus is not used in the initial verification pass. | D3: COV-002, COV-003, COV-004, COV-005
A4: NOTE-002 | B4: NCO Verification | C4: The NCO baud rate generator is verified indirectly via loopback frame integrity at each COV-001 tuning word. Direct accumulator state observation is not required by any requirement. | D4: COV-001
A5: NOTE-003 | B5: FIFO Threshold Expressions | C5: FIFO threshold coverage goals COV-004 and COV-005 use relative expressions (RX_THRESH +/- 1) rather than absolute values so they remain valid across all G_FIFO_DEPTH instantiations without test modification. | D5: COV-004, COV-005
A6: NOTE-004 | B6: Interrupt Verification Order | C6: Interrupt model verification prioritizes isolation first (COV-007 each_bit_independently) then co-occurrence (COV-008, COV-009). A combined all-sources-simultaneously scenario is explicitly not targeted — it adds complexity without additional requirement closure. | D6: COV-007, COV-008, COV-009
A7: NOTE-005 | B7: AXI SLVERR Address | C7: AXI-Lite SLVERR coverage (COV-010, COV-011) is achieved by accessing offset 0x30 which is the first undefined address above the register map. | D7: COV-010, COV-011
A8: NOTE-006 | B8: SCRATCH Test Ordering | C8: The SCRATCH register walking-ones test (COV-014) is always the first test sequence executed before any functional register access, establishing AXI-Lite connectivity as a precondition for all subsequent tests. | D8: COV-014
A9: NOTE-007 | B9: Gap Demo Requirement | C9: UART-BR-004 is intentionally absent from the [confirmed] section of the .req file in the initial demonstration. This produces a Direction A ERROR in the gap report. Closing the gap by adding the [CONFIRMED] disposition to the .req file is the live demonstration of pssgen traceability. Do not add UART-BR-004 here until after the demo. | D9: UART-BR-004, COV-013

Sheet Summary
A1: VERIFICATION SUMMARY — computed from VPR tab
A2: Family | B2: Total | C2: Covered | D2: Waived | E2: Gap | F2: % Complete | G2: Gap | H2: % Complete
A3: PAR | B3: =COUNTIF(VPR!B4:B144,"PAR") | C3: =COUNTIFS(VPR!B4:B144,"PAR",VPR!AB4:X144,"<>OPEN",VPR!AB4:X144,"<>WAIVED") | D3: =COUNTIFS(VPR!B4:B144,"PAR",VPR!K4:K144,"WAIVED") | E3: =B3-C3-D3 | F3: =IFERROR((C3+D3)/B3,0)
A4: IF | B4: =COUNTIF(VPR!B4:B144,"IF") | C4: =COUNTIFS(VPR!B4:B144,"IF",VPR!AB4:X144,"<>OPEN",VPR!AB4:X144,"<>WAIVED") | D4: =COUNTIFS(VPR!B4:B144,"IF",VPR!K4:K144,"WAIVED") | E4: =B4-C4-D4 | F4: =IFERROR((C4+D4)/B4,0)
A5: EN | B5: =COUNTIF(VPR!B4:B144,"EN") | C5: =COUNTIFS(VPR!B4:B144,"EN",VPR!AB4:X144,"<>OPEN",VPR!AB4:X144,"<>WAIVED") | D5: =COUNTIFS(VPR!B4:B144,"EN",VPR!K4:K144,"WAIVED") | E5: =B5-C5-D5 | F5: =IFERROR((C5+D5)/B5,0)
A6: BR | B6: =COUNTIF(VPR!B4:B144,"BR") | C6: =COUNTIFS(VPR!B4:B144,"BR",VPR!AB4:X144,"<>OPEN",VPR!AB4:X144,"<>WAIVED") | D6: =COUNTIFS(VPR!B4:B144,"BR",VPR!K4:K144,"WAIVED") | E6: =B6-C6-D6 | F6: =IFERROR((C6+D6)/B6,0)
A7: FF | B7: =COUNTIF(VPR!B4:B144,"FF") | C7: =COUNTIFS(VPR!B4:B144,"FF",VPR!AB4:X144,"<>OPEN",VPR!AB4:X144,"<>WAIVED") | D7: =COUNTIFS(VPR!B4:B144,"FF",VPR!K4:K144,"WAIVED") | E7: =B7-C7-D7 | F7: =IFERROR((C7+D7)/B7,0)
A8: FIFO | B8: =COUNTIF(VPR!B4:B144,"FIFO") | C8: =COUNTIFS(VPR!B4:B144,"FIFO",VPR!AB4:X144,"<>OPEN",VPR!AB4:X144,"<>WAIVED") | D8: =COUNTIFS(VPR!B4:B144,"FIFO",VPR!K4:K144,"WAIVED") | E8: =B8-C8-D8 | F8: =IFERROR((C8+D8)/B8,0)
A9: TO | B9: =COUNTIF(VPR!B4:B144,"TO") | C9: =COUNTIFS(VPR!B4:B144,"TO",VPR!AB4:X144,"<>OPEN",VPR!AB4:X144,"<>WAIVED") | D9: =COUNTIFS(VPR!B4:B144,"TO",VPR!K4:K144,"WAIVED") | E9: =B9-C9-D9 | F9: =IFERROR((C9+D9)/B9,0)
A10: INT | B10: =COUNTIF(VPR!B4:B144,"INT") | C10: =COUNTIFS(VPR!B4:B144,"INT",VPR!AB4:X144,"<>OPEN",VPR!AB4:X144,"<>WAIVED") | D10: =COUNTIFS(VPR!B4:B144,"INT",VPR!K4:K144,"WAIVED") | E10: =B10-C10-D10 | F10: =IFERROR((C10+D10)/B10,0)
A11: REG | B11: =COUNTIF(VPR!B4:B144,"REG") | C11: =COUNTIFS(VPR!B4:B144,"REG",VPR!AB4:X144,"<>OPEN",VPR!AB4:X144,"<>WAIVED") | D11: =COUNTIFS(VPR!B4:B144,"REG",VPR!K4:K144,"WAIVED") | E11: =B11-C11-D11 | F11: =IFERROR((C11+D11)/B11,0)
A12: RST | B12: =COUNTIF(VPR!B4:B144,"RST") | C12: =COUNTIFS(VPR!B4:B144,"RST",VPR!AB4:X144,"<>OPEN",VPR!AB4:X144,"<>WAIVED") | D12: =COUNTIFS(VPR!B4:B144,"RST",VPR!K4:K144,"WAIVED") | E12: =B12-C12-D12 | F12: =IFERROR((C12+D12)/B12,0)
A13: VER | B13: =COUNTIF(VPR!B4:B144,"VER") | C13: =COUNTIFS(VPR!B4:B144,"VER",VPR!AB4:X144,"<>OPEN",VPR!AB4:X144,"<>WAIVED") | D13: =COUNTIFS(VPR!B4:B144,"VER",VPR!K4:K144,"WAIVED") | E13: =B13-C13-D13 | F13: =IFERROR((C13+D13)/B13,0)
A14: TOTAL | B14: =SUM(B3:B13) | C14: =SUM(C3:C13) | D14: =SUM(D3:D13) | E14: =SUM(E3:E13) | F14: =IFERROR((C14+D14)/B14,0)

Sheet Anomalies
A2: Anomaly_ID | B2: Req_ID | C2: COV_ID | D2: Severity | E2: Status | F2: Description | G2: Root_Cause | H2: Resolution | I2: Opened_Date | J2: Closed_Date | K2: Impact | L2: Regression_Fixed
